<robot name="dumpUrdf">
	<link name = "base">
		<inertial>
			<origin rpy = "0 0 0"  xyz = "0 0 0" />
			<mass value =  "0.0001" />
			<inertia ixx = "0.0001" ixy = "0" ixz = "0" iyy = "0.0001" iyz = "0" izz = "0.0001" />
		</inertial>
	</link>
	<link name = "root">
		<inertial>
			<origin rpy = "0 0 0"  xyz = "0 0 0" />
			<mass value =  "15" />
			<inertia ixx = "0.1" ixy = "0" ixz = "0" iyy = "0.1" iyz = "0" izz = "0.1" />
		</inertial>
		<collision>
			<origin rpy = "0 0 0"  xyz = "0 0 0" />
			<geometry>
				<sphere radius="0.08" />
			</geometry>
		</collision>
	</link>
	<joint name="root" type="fixed">
		<parent link = "base" />
		<child link = "root" />
		<origin rpy = "0 0 0  " xyz ="0.0 0.0 0.0"  />
	</joint>
	<link name = "root_dammy_ori">
		<inertial>
			<origin rpy = "0 0 0"  xyz = "0 0 0" />
			<mass value =  "0.00001" />
			<inertia ixx = "0.1" ixy = "0" ixz = "0" iyy = "0.1" iyz = "0" izz = "0.1" />
		</inertial>
		<collision>
			<origin rpy = "0 0 0"  xyz = "0 0 0" />
			<geometry>
				<sphere radius="8e-08" />
			</geometry>
		</collision>
	</link>
	<joint name="root_dammy_ori" type="fixed">
		<parent link = "root" />
		<child link = "root_dammy_ori" />
		<origin rpy = "-1.57 -1.57 0 " xyz ="0.0 0.0 0.0"  />
	</joint>

	<link name = "left_hip_marker">
		<inertial>
			<origin rpy = "0 0 0"  xyz = "0 0 0" />
			<mass value =  "1e-05" />
			<inertia ixx = "0.1" ixy = "0" ixz = "0" iyy = "0.1" iyz = "0" izz = "0.1" />
		</inertial>
		<collision>
			<origin rpy = "0 0 0"  xyz = "0 0 0" />
			<geometry>
				<sphere radius="0.02" />
			</geometry>
		</collision>
	</link>
	<joint name="left_hip_marker" type="revolute">
		<parent link = "root_dammy_ori" />
		<child link = "left_hip_marker" />
		<limit effort="1000.0" lower= "-2.5" upper= "1.4" velocity="0.5" />
		<origin rpy = "0 0 0" xyz ="0.0 0.12 0.0"  />
		<axis xyz = "0.0 1.0 0.0" />
	</joint>
	<link name = "left_hip_rx">
		<inertial>
			<origin rpy = "0 0 0"  xyz = "0 0 0" />
			<mass value =  "1e-05" />
			<inertia ixx = "0.1" ixy = "0" ixz = "0" iyy = "0.1" iyz = "0" izz = "0.1" />
		</inertial>
		<collision>
			<origin rpy = "0 0 0"  xyz = "0 0 0" />
			<geometry>
				<sphere radius="2e-06" />
			</geometry>
		</collision>
	</link>
	<joint name="left_hip_rx" type="revolute">
		<parent link = "root_dammy_ori" />
		<child link = "left_hip_rx" />
		<limit effort="1000.0" lower= "-2.5" upper= "1.4" velocity="0.5" />
		<origin rpy = "0 0 0" xyz ="-0.027788243996403342 0.0854337925062539 -0.10986151319674316"  />
		<axis xyz = "0.0 1.0 0.0" />
	</joint>
	<link name = "left_hip_ry">
		<inertial>
			<origin rpy = "0 0 0"  xyz = "0 0 0" />
			<mass value =  "1e-05" />
			<inertia ixx = "0.1" ixy = "0" ixz = "0" iyy = "0.1" iyz = "0" izz = "0.1" />
		</inertial>
		<collision>
			<origin rpy = "0 0 0 "  xyz = "0 0 0" />
			<geometry>
				<sphere radius="2e-06" />
			</geometry>
		</collision>
	</link>
	<joint name="left_hip_ry" type="revolute">
		<parent link = "left_hip_rx" />
		<child link = "left_hip_ry" />
		<limit effort="1000.0" lower= "-0.6" upper= "0.6" velocity="0.5" />
		<origin rpy = "0 0 0" xyz ="0.0 0.0 0.0"  />
		<axis xyz = "0.0 0.0 1.0" />
	</joint>
	<link name = "left_hip_rz">
		<inertial>
			<origin rpy = "0 0 0"  xyz = "0 0 0" />
			<mass value =  "1e-05" />
			<inertia ixx = "0.1" ixy = "0" ixz = "0" iyy = "0.1" iyz = "0" izz = "0.1" />
		</inertial>
		<collision>
			<origin rpy = "0 0 0"  xyz = "0 0 0" />
			<geometry>
				<sphere radius="2e-06" />
			</geometry>
		</collision>
	</link>
	<joint name="left_hip_rz" type="revolute">
		<parent link = "left_hip_ry" />
		<child link = "left_hip_rz" />
		<limit effort="1000.0" lower= "-0.8" upper= "1.4" velocity="0.5" />
		<origin rpy = "0 0 0" xyz ="0.0 0.0 0.0"  />
		<axis xyz = "1.0 0.0 0.0" />
	</joint>
	<joint name="right_hip_marker" type="revolute">
		<parent link = "root_dammy_ori" />
		<child link = "right_hip_marker" />
		<limit effort="1000.0" lower= "-2.5" upper= "1.4" velocity="0.5" />
		<origin rpy = "0 0 0" xyz ="0.0 -0.12 0.0"  />
		<axis xyz = "0.0 1.0 0.0" />
	</joint>
	<link name = "right_hip_marker">
		<inertial>
			<origin rpy = "0 0 0"  xyz = "0 0 0" />
			<mass value =  "1e-05" />
			<inertia ixx = "0.1" ixy = "0" ixz = "0" iyy = "0.1" iyz = "0" izz = "0.1" />
		</inertial>
		<collision>
			<origin rpy = "0 0 0"  xyz = "0 0 0" />
			<geometry>
				<sphere radius="2e-06" />
			</geometry>
		</collision>
	</link>
	<link name = "right_hip_rx">
		<inertial>
			<origin rpy = "0 0 0"  xyz = "0 0 0" />
			<mass value =  "1e-05" />
			<inertia ixx = "0.1" ixy = "0" ixz = "0" iyy = "0.1" iyz = "0" izz = "0.1" />
		</inertial>
		<collision>
			<origin rpy = "0 0 0"  xyz = "0 0 0" />
			<geometry>
				<sphere radius="2e-06" />
			</geometry>
		</collision>
	</link>
	<joint name="right_hip_rx" type="revolute">
		<parent link = "root_dammy_ori" />
		<child link = "right_hip_rx" />
		<limit effort="1000.0" lower= "-2.5" upper= "1.4" velocity="0.5" />
		<origin rpy = "0 0 0" xyz ="-0.027788243996403342 -0.0854337925062539 -0.10986151319674316"  />
		<axis xyz = "0.0 1.0 0.0" />
	</joint>
	<link name = "right_hip_ry">
		<inertial>
			<origin rpy = "0 0 0"  xyz = "0 0 0" />
			<mass value =  "1e-05" />
			<inertia ixx = "0.1" ixy = "0" ixz = "0" iyy = "0.1" iyz = "0" izz = "0.1" />
		</inertial>
		<collision>
			<origin rpy = "0 0 0"  xyz = "0 0 0" />
			<geometry>
				<sphere radius="2e-06" />
			</geometry>
		</collision>
	</link>
	<joint name="right_hip_ry" type="revolute">
		<parent link = "right_hip_rx" />
		<child link = "right_hip_ry" />
		<limit effort="1000.0" lower= "-0.6" upper= "0.6" velocity="0.5" />
		<origin rpy = "0 0 0" xyz ="0.0 0.0 0.0"  />
		<axis xyz = "0.0 0.0 1.0" />
	</joint>
	<link name = "right_hip_rz">
		<inertial>
			<origin rpy = "0 0 0"  xyz = "0 0 0" />
			<mass value =  "1e-05" />
			<inertia ixx = "0.1" ixy = "0" ixz = "0" iyy = "0.1" iyz = "0" izz = "0.1" />
		</inertial>
		<collision>
			<origin rpy = "0 0 0"  xyz = "0 0 0" />
			<geometry>
				<sphere radius="2e-05" />
			</geometry>
		</collision>
	</link>
	<joint name="right_hip_rz" type="revolute">
		<parent link = "right_hip_ry" />
		<child link = "right_hip_rz" />
		<limit effort="1000.0" lower= "-1.4" upper= "0.8" velocity="0.5" />
		<origin rpy = "0 0 0" xyz ="0.0 0.0 0.0"  />
		<axis xyz = "1.0 0.0 0.0" />
	</joint>
	<link name = "spine_2_limb">
		<inertial>
			<origin rpy = "0 0 0"  xyz = "-0.009163575 0.001104645 0.0307225" />
			<mass value =  "4" />
			<inertia ixx = "0.1" ixy = "0" ixz = "0" iyy = "0.1" iyz = "0" izz = "0.1" />
		</inertial>
		<collision>
			<origin rpy = "0 0 0"  xyz = "-0.009163575 0.001104645 0.0307225" />
			<geometry>
				<sphere radius="0.07" />
			</geometry>
		</collision>
	</link>
	<joint name="rootdammy" type="fixed">
		<parent link = "root_dammy_ori" />
		<child link = "spine_2_limb" />
		<origin rpy = "0 0 0" xyz ="0.0 0.0 0.0"  />
	</joint>
	<link name = "spine_2_rx">
		<inertial>
			<origin rpy = "0 0 0"  xyz = "0 0 0" />
			<mass value =  "1e-05" />
			<inertia ixx = "0.1" ixy = "0" ixz = "0" iyy = "0.1" iyz = "0" izz = "0.1" />
		</inertial>
		<collision>
			<origin rpy = "0 0 0"  xyz = "0 0 0" />
			<geometry>
				<sphere radius="2e-06" />
			</geometry>
		</collision>
	</link>
	<joint name="spine_2_rx" type="fixed">
		<parent link = "spine_2_limb" />
		<child link = "spine_2_rx" />
		<origin rpy = "0 0 0" xyz ="-0.04089248307203248 0.004929481884865384 0.13709925560499234"/>
	</joint>
	<link name = "spine_2_ry">
		<inertial>
			<origin rpy = "0 0 0"  xyz = "0 0 0" />
			<mass value =  "1e-05" />
			<inertia ixx = "0.1" ixy = "0" ixz = "0" iyy = "0.1" iyz = "0" izz = "0.1" />
		</inertial>
		<collision>
			<origin rpy = "0 0 0"  xyz = "0 0 0" />
			<geometry>
				<sphere radius="2e-06" />
			</geometry>
		</collision>
	</link>
	<joint name="spine_2_ry" type="fixed">
		<parent link = "spine_2_rx" />
		<child link = "spine_2_ry" />
		<origin rpy = "0 0 0" xyz ="0.0 0.0 0.0"  />
	</joint>
	<link name = "spine_2_rz">
		<inertial>
			<origin rpy = "0 0 0"  xyz = "0 0 0" />
			<mass value =  "1e-05" />
			<inertia ixx = "0.1" ixy = "0" ixz = "0" iyy = "0.1" iyz = "0" izz = "0.1" />
		</inertial>
		<collision>
			<origin rpy = "0 0 0"  xyz = "0 0 0" />
			<geometry>
				<sphere radius="2e-05" />
			</geometry>
		</collision>
	</link>
	<joint name="spine_2_rz" type="fixed">
		<parent link = "spine_2_ry" />
		<child link = "spine_2_rz" />
		<origin rpy = "0 0 0" xyz ="0.0 0.0 0.0"  />
	</joint>
	<link name = "left_knee_limb">
		<inertial>
			<origin rpy = "0 0 0"  xyz = "0.0021889500000000003 0.041133375 -0.197404" />
			<mass value =  "7.3" />
			<inertia ixx = "0.1" ixy = "0" ixz = "0" iyy = "0.1" iyz = "0" izz = "0.1" />
		</inertial>
		<collision>
			<origin rpy = "0 0 0"  xyz = "0.0021889500000000003 0.041133375 -0.197404" />
			<geometry>
				<capsule length="0.3136804707319758" radius="0.06" />
			</geometry>
		</collision>
	</link>
	<joint name="left_hip_rzdammy" type="fixed">
		<parent link = "left_hip_rz" />
		<child link = "left_knee_limb" />
		<origin rpy = "0 0 0" xyz ="0.0 0.0 0.0"  />
	</joint>
	<link name = "left_knee_rx">
		<inertial>
			<origin rpy = "0 0 0"  xyz = "0 0 0" />
			<mass value =  "1e-05" />
			<inertia ixx = "0.1" ixy = "0" ixz = "0" iyy = "0.1" iyz = "0" izz = "0.1" />
		</inertial>
		<collision>
			<origin rpy = "0 0 0"  xyz = "0 0 0" />
			<geometry>
				<sphere radius="2e-06" />
			</geometry>
		</collision>
	</link>
	<joint name="left_knee_rx" type="revolute">
		<parent link = "left_knee_limb" />
		<child link = "left_knee_rx" />
		<limit effort="1000.0" lower= "-0.1" upper= "2.5" velocity="0.5" />
		<origin rpy = "0 0 0" xyz ="0.009018984740918595 0.04587210271587955 -0.4216773558863491"  />
		<axis xyz = "0.0 1.0 0.0" />
	</joint>
	<link name = "left_knee_ry">
		<inertial>
			<origin rpy = "0 0 0"  xyz = "0 0 0" />
			<mass value =  "1e-05" />
			<inertia ixx = "0.1" ixy = "0" ixz = "0" iyy = "0.1" iyz = "0" izz = "0.1" />
		</inertial>
		<collision>
			<origin rpy = "0 0 0"  xyz = "0 0 0" />
			<geometry>
				<sphere radius="2e-06" />
			</geometry>
		</collision>
	</link>
	<joint name="left_knee_ry" type="fixed">
		<parent link = "left_knee_rx" />
		<child link = "left_knee_ry" />
		<origin rpy = "0 0 0" xyz ="0.0 0.0 0.0"  />
	</joint>
	<link name = "left_knee_rz">
		<inertial>
			<origin rpy = "0 0 0"  xyz = "0 0 0" />
			<mass value =  "1e-05" />
			<inertia ixx = "0.1" ixy = "0" ixz = "0" iyy = "0.1" iyz = "0" izz = "0.1" />
		</inertial>
		<collision>
			<origin rpy = "0 0 0"  xyz = "0 0 0" />
			<geometry>
				<sphere radius="2e-05" />
			</geometry>
		</collision>
	</link>
	<joint name="left_knee_rz" type="fixed">
		<parent link = "left_knee_ry" />
		<child link = "left_knee_rz" />
		<origin rpy = "0 0 0" xyz ="0.0 0.0 0.0"  />
	</joint>
	<link name = "right_knee_limb">
		<inertial>
			<origin rpy = "0 0 0"  xyz = "-0.00108367 -0.041133375 -0.19648575" />
			<mass value =  "7.3" />
			<inertia ixx = "0.1" ixy = "0" ixz = "0" iyy = "0.1" iyz = "0" izz = "0.1" />
		</inertial>
		<collision>
			<origin rpy = "0 0 0"  xyz = "-0.00108367 -0.041133375 -0.19648575" />
			<geometry>
				<capsule length="0.31066211070980765" radius="0.06" />
			</geometry>
		</collision>
	</link>
	<joint name="right_hip_rzdammy" type="fixed">
		<parent link = "right_hip_rz" />
		<child link = "right_knee_limb" />
		<origin rpy = "0 0 0" xyz ="0.0 0.0 0.0"  />
	</joint>
	<link name = "right_knee_rx">
		<inertial>
			<origin rpy = "0 0 0"  xyz = "0 0 0" />
			<mass value =  "1e-05" />
			<inertia ixx = "0.1" ixy = "0" ixz = "0" iyy = "0.1" iyz = "0" izz = "0.1" />
		</inertial>
		<collision>
			<origin rpy = "0 0 0"  xyz = "0 0 0" />
			<geometry>
				<sphere radius="2e-06" />
			</geometry>
		</collision>
	</link>
	<joint name="right_knee_rx" type="revolute">
		<parent link = "right_knee_limb" />
		<child link = "right_knee_rx" />
		<limit effort="1000.0" lower= "-0.1" upper= "2.5" velocity="0.5" />
		<origin rpy = "0 0 0" xyz ="-0.004373491320651404 -0.04448658369519724 -0.41004197019861993"  />
		<axis xyz = "0.0 1.0 0.0" />
	</joint>
	<link name = "right_knee_ry">
		<inertial>
			<origin rpy = "0 0 0"  xyz = "0 0 0" />
			<mass value =  "1e-05" />
			<inertia ixx = "0.1" ixy = "0" ixz = "0" iyy = "0.1" iyz = "0" izz = "0.1" />
		</inertial>
		<collision>
			<origin rpy = "0 0 0"  xyz = "0 0 0" />
			<geometry>
				<sphere radius="2e-06" />
			</geometry>
		</collision>
	</link>
	<joint name="right_knee_ry" type="fixed">
		<parent link = "right_knee_rx" />
		<child link = "right_knee_ry" />
		<origin rpy = "0 0 0" xyz ="0.0 0.0 0.0"  />
	</joint>
	<link name = "right_knee_rz">
		<inertial>
			<origin rpy = "0 0 0"  xyz = "0 0 0" />
			<mass value =  "1e-05" />
			<inertia ixx = "0.1" ixy = "0" ixz = "0" iyy = "0.1" iyz = "0" izz = "0.1" />
		</inertial>
		<collision>
			<origin rpy = "0 0 0"  xyz = "0 0 0" />
			<geometry>
				<sphere radius="2e-05" />
			</geometry>
		</collision>
	</link>
	<joint name="right_knee_rz" type="fixed">
		<parent link = "right_knee_ry" />
		<child link = "right_knee_rz" />
		<origin rpy = "0 0 0" xyz ="0.0 0.0 0.0"  />
	</joint>
	<link name = "spine_3_limb">
		<inertial>
			<origin rpy = "0 0 0"  xyz = "0.006746275 0.001106725 0.030545999999999995" />
			<mass value =  "3" />
			<inertia ixx = "0.1" ixy = "0" ixz = "0" iyy = "0.1" iyz = "0" izz = "0.1" />
		</inertial>
		<collision>
			<origin rpy = "0 0 0"  xyz = "0.006746275 0.001106725 0.034345999999999995" />
			<geometry>
				<sphere radius="0.07" />
			</geometry>
		</collision>
	</link>
	<joint name="spine_2_rzdammy" type="fixed">
		<parent link = "spine_2_rz" />
		<child link = "spine_3_limb" />
		<origin rpy = "0 0 0" xyz ="0.0 0.0 0.0"  />
	</joint>
	<link name = "spine_3_rx">
		<inertial>
			<origin rpy = "0 0 0"  xyz = "0 0 0" />
			<mass value =  "1e-05" />
			<inertia ixx = "0.1" ixy = "0" ixz = "0" iyy = "0.1" iyz = "0" izz = "0.1" />
		</inertial>
		<collision>
			<origin rpy = "0 0 0"  xyz = "0 0 0" />
			<geometry>
				<sphere radius="2e-06" />
			</geometry>
		</collision>
	</link>
	<joint name="spine_3_rx" type="fixed">
		<parent link = "spine_3_limb" />
		<child link = "spine_3_rx" />
		<origin rpy = "0 0 0" xyz ="0.03432986899130181 0.005631807813852607 0.1747769962498196"  />
	</joint>
	<link name = "spine_3_ry">
		<inertial>
			<origin rpy = "0 0 0"  xyz = "0 0 0" />
			<mass value =  "1e-05" />
			<inertia ixx = "0.1" ixy = "0" ixz = "0" iyy = "0.1" iyz = "0" izz = "0.1" />
		</inertial>
		<collision>
			<origin rpy = "0 0 0"  xyz = "0 0 0" />
			<geometry>
				<sphere radius="2e-06" />
			</geometry>
		</collision>
	</link>
	<joint name="spine_3_ry" type="fixed">
		<parent link = "spine_3_rx" />
		<child link = "spine_3_ry" />
		<origin rpy = "0 0 0" xyz ="0.0 0.0 0.0"  />
	</joint>
	<link name = "spine_3_rz">
		<inertial>
			<origin rpy = "0 0 0"  xyz = "0 0 0" />
			<mass value =  "1e-05" />
			<inertia ixx = "0.1" ixy = "0" ixz = "0" iyy = "0.1" iyz = "0" izz = "0.1" />
		</inertial>
		<collision>
			<origin rpy = "0 0 0"  xyz = "0 0 0" />
			<geometry>
				<sphere radius="2e-05" />
			</geometry>
		</collision>
	</link>
	<joint name="spine_3_rz" type="fixed">
		<parent link = "spine_3_ry" />
		<child link = "spine_3_rz" />
		<origin rpy = "0 0 0" xyz ="0.0 0.0 0.0"  />
	</joint>
	<link name = "left_ankle_limb">
		<inertial>
			<origin rpy = "0 0 0"  xyz = "-0.00916405 -0.0035968000000000003 -0.2070435" />
			<mass value =  "5.16" />
			<inertia ixx = "0.1" ixy = "0" ixz = "0" iyy = "0.1" iyz = "0" izz = "0.1" />
		</inertial>
		<collision>
			<origin rpy = "0 0 0"  xyz = "-0.00916405 -0.0035968000000000003 -0.2470435" />
			<geometry>
				<capsule length="0.3838647836618638" radius="0.05" />
			</geometry>
		</collision>
	</link>
	<joint name="left_knee_rzdammy" type="fixed">
		<parent link = "left_knee_rz" />
		<child link = "left_ankle_limb" />
		<origin rpy = "0 0 0" xyz ="0.0 0.0 0.0"  />
	</joint>
	<link name = "left_ankle_rx">
		<inertial>
			<origin rpy = "0 0 0"  xyz = "0 0 0" />
			<mass value =  "1e-05" />
			<inertia ixx = "0.1" ixy = "0" ixz = "0" iyy = "0.1" iyz = "0" izz = "0.1" />
		</inertial>
		<collision>
			<origin rpy = "0 0 0"  xyz = "0 0 0" />
			<geometry>
				<sphere radius="2e-06" />
			</geometry>
		</collision>
	</link>
	<joint name="left_ankle_rx" type="revolute">
		<parent link = "left_ankle_limb" />
		<child link = "left_ankle_rx" />
		<limit effort="1000.0" lower= "-0.4" upper= "0.7" velocity="0.5" />
		<origin rpy = "0 0 0" xyz ="-0.03838226054244939 -0.015064661881927966 -0.44226868380209217"  />
		<axis xyz = "0.0 1.0 0.0" />
	</joint>
	<link name = "left_ankle_ry">
		<inertial>
			<origin rpy = "0 0 0"  xyz = "0 0 0" />
			<mass value =  "1e-05" />
			<inertia ixx = "0.1" ixy = "0" ixz = "0" iyy = "0.1" iyz = "0" izz = "0.1" />
		</inertial>
		<collision>
			<origin rpy = "0 0 0"  xyz = "0 0 0" />
			<geometry>
				<sphere radius="2e-06" />
			</geometry>
		</collision>
	</link>
	<joint name="left_ankle_ry" type="revolute">
		<parent link = "left_ankle_rx" />
		<child link = "left_ankle_ry" />
		<limit effort="1000.0" lower= "-0.5" upper= "0.5" velocity="0.5" />
		<origin rpy = "0 0 0" xyz ="0.0 0.0 0.0"  />
		<axis xyz = "0.0 0.0 1.0" />
	</joint>
	<link name = "left_ankle_rz">
		<inertial>
			<origin rpy = "0 0 0"  xyz = "0 0 0" />
			<mass value =  "1e-05" />
			<inertia ixx = "0.1" ixy = "0" ixz = "0" iyy = "0.1" iyz = "0" izz = "0.1" />
		</inertial>
		<collision>
			<origin rpy = "0 0 0"  xyz = "0 0 0" />
			<geometry>
				<sphere radius="2e-05" />
			</geometry>
		</collision>
	</link>
	<joint name="left_ankle_rz" type="revolute">
		<parent link = "left_ankle_ry" />
		<child link = "left_ankle_rz" />
		<limit effort="1000.0" lower= "-0.4" upper= "0.4" velocity="0.5" />
		<origin rpy = "0 0 0" xyz ="0.0 0.0 0.0"  />
		<axis xyz = "1.0 0.0 0.0" />
	</joint>
	<link name = "right_ankle_limb">
		<inertial>
			<origin rpy = "0 0 0"  xyz = "-0.00916405 -0.0035968000000000003 -0.2470435" />
			<mass value =  "5.16" />
			<inertia ixx = "0.1" ixy = "0" ixz = "0" iyy = "0.1" iyz = "0" izz = "0.1" />
		</inertial>
		<collision>
			<origin rpy = "0 0 0"  xyz = "-0.00916405 -0.0035968000000000003 -0.2470435" />
			<geometry>
				<capsule length="0.3838647836618638" radius="0.05" />
			</geometry>
		</collision>
	</link>
	<joint name="right_knee_rzdammy" type="fixed">
		<parent link = "right_knee_rz" />
		<child link = "right_ankle_limb" />
		<origin rpy = "0 0 0" xyz ="0.0 0.0 0.0"  />
	</joint>
	<link name = "right_ankle_rx">
		<inertial>
			<origin rpy = "0 0 0"  xyz = "0 0 0" />
			<mass value =  "1e-05" />
			<inertia ixx = "0.1" ixy = "0" ixz = "0" iyy = "0.1" iyz = "0" izz = "0.1" />
		</inertial>
		<collision>
			<origin rpy = "0 0 0"  xyz = "0 0 0" />
			<geometry>
				<sphere radius="2e-06" />
			</geometry>
		</collision>
	</link>
	<joint name="right_ankle_rx" type="revolute">
		<parent link = "right_ankle_limb" />
		<child link = "right_ankle_rx" />
		<limit effort="1000.0" lower= "-0.4" upper= "0.7" velocity="0.5" />
		<origin rpy = "0 0 0" xyz ="-0.03546846062498642 0.01973680926690652 -0.4343713079542145"  />
		<axis xyz = "0.0 1.0 0.0" />
	</joint>
	<link name = "right_ankle_ry">
		<inertial>
			<origin rpy = "0 0 0"  xyz = "0 0 0" />
			<mass value =  "1e-05" />
			<inertia ixx = "0.1" ixy = "0" ixz = "0" iyy = "0.1" iyz = "0" izz = "0.1" />
		</inertial>
		<collision>
			<origin rpy = "0 0 0"  xyz = "0 0 0" />
			<geometry>
				<sphere radius="2e-06" />
			</geometry>
		</collision>
	</link>
	<joint name="right_ankle_ry" type="revolute">
		<parent link = "right_ankle_rx" />
		<child link = "right_ankle_ry" />
		<limit effort="1000.0" lower= "-0.5" upper= "0.5" velocity="0.5" />
		<origin rpy = "0 0 0" xyz ="0.0 0.0 0.0"  />
		<axis xyz = "0.0 0.0 1.0" />
	</joint>
	<link name = "right_ankle_rz">
		<inertial>
			<origin rpy = "0 0 0"  xyz = "0 0 0" />
			<mass value =  "1e-05" />
			<inertia ixx = "0.1" ixy = "0" ixz = "0" iyy = "0.1" iyz = "0" izz = "0.1" />
		</inertial>
		<collision>
			<origin rpy = "0 0 0"  xyz = "0 0 0" />
			<geometry>
				<sphere radius="2e-05" />
			</geometry>
		</collision>
	</link>
	<joint name="right_ankle_rz" type="revolute">
		<parent link = "right_ankle_ry" />
		<child link = "right_ankle_rz" />
		<limit effort="1000.0" lower= "-0.4" upper= "0.4" velocity="0.5" />
		<origin rpy = "0 0 0" xyz ="0.0 0.0 0.0"  />
		<axis xyz = "1.0 0.0 0.0" />
		<origin rpy = "0 0 0" xyz ="0.0 0.0 0.0"  />
	</joint>
	<link name = "spine_4_limb">
		<inertial>
			<origin rpy = "0 0 0"  xyz = "0.000602165 -0.000534685 0.01393855" />
			<mass value =  "3" />
			<inertia ixx = "0.1" ixy = "0" ixz = "0" iyy = "0.1" iyz = "0" izz = "0.1" />
		</inertial>
		<collision>
			<origin rpy = "0 0 0"  xyz = "0.000602165 -0.000534685 0.01393855" />
			<geometry>
				<sphere radius="0.07" />
			</geometry>
		</collision>
	</link>
	<joint name="spine_3_rzdammy" type="fixed">
		<parent link = "spine_3_rz" />
		<child link = "spine_4_limb" />
		<origin rpy = "0 0 0" xyz ="0.0 0.0 0.0"  />
	</joint>
	<link name = "spine_4_rx">
		<inertial>
			<origin rpy = "0 0 0"  xyz = "0 0 0" />
			<mass value =  "1e-05" />
			<inertia ixx = "0.1" ixy = "0" ixz = "0" iyy = "0.1" iyz = "0" izz = "0.1" />
		</inertial>
		<collision>
			<origin rpy = "0 0 0"  xyz = "0 0 0" />
			<geometry>
				<sphere radius="2e-06" />
			</geometry>
		</collision>
	</link>
	<joint name="spine_4_rx" type="fixed">
		<parent link = "spine_4_limb" />
		<child link = "spine_4_rx" />
		<origin rpy = "0 0 0" xyz ="0.0030642459077264493 -0.0027208594374842723 0.07092930475391379"  />
	</joint>
	<link name = "spine_4_ry">
		<inertial>
			<origin rpy = "0 0 0"  xyz = "0 0 0" />
			<mass value =  "1e-05" />
			<inertia ixx = "0.1" ixy = "0" ixz = "0" iyy = "0.1" iyz = "0" izz = "0.1" />
		</inertial>
		<collision>
			<origin rpy = "0 0 0"  xyz = "0 0 0" />
			<geometry>
				<sphere radius="2e-06" />
			</geometry>
		</collision>
	</link>
	<joint name="spine_4_ry" type="fixed">
		<parent link = "spine_4_rx" />
		<child link = "spine_4_ry" />
		<origin rpy = "0 0 0" xyz ="0.0 0.0 0.0"  />
	</joint>
	<link name = "spine_4_rz">
		<inertial>
			<origin rpy = "0 0 0"  xyz = "0 0 0" />
			<mass value =  "1e-05" />
			<inertia ixx = "0.1" ixy = "0" ixz = "0" iyy = "0.1" iyz = "0" izz = "0.1" />
		</inertial>
		<collision>
			<origin rpy = "0 0 0"  xyz = "0 0 0" />
			<geometry>
				<sphere radius="2e-05" />
			</geometry>
		</collision>
	</link>
	<joint name="spine_4_rz" type="fixed">
		<parent link = "spine_4_ry" />
		<child link = "spine_4_rz" />
		<origin rpy = "0 0 0" xyz ="0.0 0.0 0.0"  />
	</joint>
	<link name = "left_foot_limb">
		<inertial>
			<origin rpy = "0 0 0"  xyz = "0.0453665 0.0 -0.065257650000000004" />
			<mass value =  "1.8" />
			<inertia ixx = "0.1" ixy = "0" ixz = "0" iyy = "0.1" iyz = "0" izz = "0.1" />
		</inertial>
		<collision>
			<origin rpy = "0 0 0"  xyz = "0.0453665 0.0 -0.065257650000000004" />
			<geometry>
				<box size="0.1475 0.08 0.0125" />
			</geometry>
		</collision>
	</link>
	<joint name="left_ankle_rzdammy" type="fixed">
		<parent link = "left_ankle_rz" />
		<child link = "left_foot_limb" />
		<origin rpy = "0 0 0" xyz ="0.0 0.0 0.0"  />
	</joint>
	<link name = "left_heel">
		<inertial>
			<origin rpy = "0 0 0"  xyz = "0 0 0" />
			<mass value =  "1e-05" />
			<inertia ixx = "0.1" ixy = "0" ixz = "0" iyy = "0.1" iyz = "0" izz = "0.1" />
		</inertial>
		<collision>
			<origin rpy ="1.5708 0 0" xyz = "0 0 0" />
            <geometry>
				<capsule length="0.07680000000000001" radius="0.01"  />
			</geometry>
		</collision>
	</link>
	<joint name="left_heel" type="revolute">
		<parent link = "left_foot_limb" />
		<child link = "left_heel" />

		<limit effort="1000.0" lower= "-0.6" upper= "0.6" velocity="0.5" />
		<origin rpy = "0 0 0" xyz = "0  0 -0.07474703957058937"  />
		<axis xyz = "0.0 0.000000001 0.0" />
	</joint>
	<link name = "left_toe">
		<inertial>
			<origin rpy = "0 0 0"  xyz = "0 0 0" />
			<mass value =  "1e-05" />
			<inertia ixx = "0.1" ixy = "0" ixz = "0" iyy = "0.1" iyz = "0" izz = "0.1" />
		</inertial>
		<collision>
			<origin rpy ="1.5708 0 0"  xyz = "0 0 0" />
            <geometry>
				<capsule length="0.07680000000000001" radius="0.01"  />
			</geometry>
		</collision>
	</link>
	<joint name="left_toe" type="revolute">
		<parent link = "left_heel" />
		<child link = "left_toe" />
		<origin rpy = "0 0 0" xyz ="0.11597439100201726 0 0"  />
		<limit effort="1000.0" lower= "-0.6" upper= "0.6" velocity="0.5" />
		<axis xyz = "0.0 1.0 0.0" />
	</joint>


	<link name = "right_foot_limb">
		<inertial>
			<origin rpy = "0 0 0"  xyz = "0.0453665 0 -0.065257650000000004" />
			<mass value =  "1.8" />
			<inertia ixx = "0.1" ixy = "0" ixz = "0" iyy = "0.1" iyz = "0" izz = "0.1" />
		</inertial>
		<collision>
			<origin rpy = "0 0 0"  xyz = "0.0453665 0 -0.065257650000000004" />
			<geometry>
				<box size="0.1475 0.08 0.0125" />
			</geometry>
		</collision>
	</link>
	<joint name="right_ankle_rzdammy" type="fixed">
		<parent link = "right_ankle_rz" />
		<child link = "right_foot_limb" />
		<origin rpy = "0 0 0" xyz ="0.0 0.0 0.0"  />
	</joint>

	<link name = "right_heel">
		<inertial>
			<origin rpy = "0 0 0"  xyz = "0 0 0" />
			<mass value =  "1e-05" />
			<inertia ixx = "0.1" ixy = "0" ixz = "0" iyy = "0.1" iyz = "0" izz = "0.1" />
		</inertial>
		<collision>
			<origin rpy ="1.5708 0 0" xyz = "0 0 0" />
            <geometry>
				<capsule length="0.07680000000000001" radius="0.01"  />
			</geometry>
		</collision>
	</link>
	<joint name="right_heel" type="revolute">
		<parent link = "right_foot_limb" />
		<child link = "right_heel" />

		<limit effort="1000.0" lower= "-0.6" upper= "0.6" velocity="0.5" />
		<origin rpy = "0 0 0" xyz = "0  0 -0.07474"  />
		<axis xyz = "0.0 0.000000001 0.0" />
	</joint>
	<link name = "right_toe">
		<inertial>
			<origin rpy = "0 0 0"  xyz = "0 0 0" />
			<mass value =  "1e-05" />
			<inertia ixx = "0.1" ixy = "0" ixz = "0" iyy = "0.1" iyz = "0" izz = "0.1" />
		</inertial>
		<collision>
			<origin rpy ="1.5708 0 0"  xyz = "0 0 0" />
            <geometry>
				<capsule length="0.07680000000000001" radius="0.01"  />
			</geometry>
		</collision>
	</link>
	<joint name="right_toe" type="revolute">
		<parent link = "right_heel" />
		<child link = "right_toe" />
		<origin rpy = "0 0 0" xyz ="0.11 0 0"  />
		<limit effort="1000.0" lower= "-0.6" upper= "0.6" velocity="0.5" />
		<axis xyz = "0.0 1.0 0.0" />
	</joint>
	<link name = "chest_limb">
		<inertial>
			<origin rpy = "0 0 0"  xyz = "-0.0078011999999999995 -0.0033519500000000002 0.052503749999999995" />
			<mass value =  "1" />
			<inertia ixx = "0.1" ixy = "0" ixz = "0" iyy = "0.1" iyz = "0" izz = "0.1" />
		</inertial>
		<collision>
			<origin rpy = "0 0 0"  xyz = "-0.0078011999999999995 -0.0033519500000000002 0.052503749999999995" />
			<geometry>
				<sphere radius="0.08" />
			</geometry>
		</collision>
	</link>
	<joint name="spine_4_rzdammy" type="fixed">
		<parent link = "spine_4_rz" />
		<child link = "chest_limb" />
		<origin rpy = "0 0 0" xyz ="0.0 0.0 0.0"  />
	</joint>
	<link name = "neck_rx">
		<inertial>
			<origin rpy = "0 0 0"  xyz = "0 0 0" />
			<mass value =  "1e-05" />
			<inertia ixx = "0.1" ixy = "0" ixz = "0" iyy = "0.1" iyz = "0" izz = "0.1" />
		</inertial>
		<collision>
			<origin rpy = "0 0 0"  xyz = "0 0 0" />
			<geometry>
				<sphere radius="2e-06" />
			</geometry>
		</collision>
	</link>
	<joint name="neck_rx" type="revolute">
		<parent link = "chest_limb" />
		<child link = "neck_rx" />
		<limit effort="1000.0" lower= "-0.6" upper= "0.6" velocity="0.5" />
		<origin rpy = "0 0 0" xyz ="-0.031204799999999998 -0.013407800000000001 0.13001499999999998"  />
		<axis xyz = "0.0 1.0 0.0" />
	</joint>
	<link name = "neck_ry">
		<inertial>
			<origin rpy = "0 0 0"  xyz = "0 0 0" />
			<mass value =  "1e-05" />
			<inertia ixx = "0.1" ixy = "0" ixz = "0" iyy = "0.1" iyz = "0" izz = "0.1" />
		</inertial>
		<collision>
			<origin rpy = "0 0 0"  xyz = "0 0 0" />
			<geometry>
				<sphere radius="2e-06" />
			</geometry>
		</collision>
	</link>
	<joint name="neck_ry" type="revolute">
		<parent link = "neck_rx" />
		<child link = "neck_ry" />
		<limit effort="1000.0" lower= "-0.6" upper= "0.6" velocity="0.5" />
		<origin rpy = "0 0 0" xyz ="0.0 0.0 0.0"  />
		<axis xyz = "0.0 0.0 1.0" />
	</joint>
	<link name = "neck_rz">
		<inertial>
			<origin rpy = "0 0 0"  xyz = "0 0 0 " />
			<mass value =  "1e-05" />
			<inertia ixx = "0.1" ixy = "0" ixz = "0" iyy = "0.1" iyz = "0" izz = "0.1" />
		</inertial>
		<collision>
			<origin rpy = "0 0 0"  xyz = "0 0 0 " />
			<geometry>
				<sphere radius="2e-07" />
			</geometry>
		</collision>
	</link>
	<joint name="neck_rz" type="revolute">
		<parent link = "neck_ry" />
		<child link = "neck_rz" />
		<limit effort="1000.0" lower= "-0.3" upper= "0.3" velocity="0.5" />
		<origin rpy = "0 0 0" xyz ="0.0 0.0 0.0"  />
		<axis xyz = "1.0 0.0 0.0" />
	</joint>
	<link name = "left_clavicle_rx">
		<inertial>
			<origin rpy = "0 0 0"  xyz = "0 0 0" />
			<mass value =  "1e-05" />
			<inertia ixx = "0.1" ixy = "0" ixz = "0" iyy = "0.1" iyz = "0" izz = "0.1" />
		</inertial>
		<collision>
			<origin rpy = "0 0 0"  xyz = "0 0 0" />
			<geometry>
				<sphere radius="2e-06" />
			</geometry>
		</collision>
	</link>
	<joint name="left_clavicle_rx" type="fixed">
		<parent link = "spine_4_rz" />
		<child link = "left_clavicle_rx" />
		<origin rpy = "0 0 0" xyz ="-0.01361165096929337 0.05255691343183243 0.083880162118844"  />
	</joint>
	<link name = "left_clavicle_ry">
		<inertial>
			<origin rpy = "0 0 0"  xyz = "0 0 0" />
			<mass value =  "1e-05" />
			<inertia ixx = "0.1" ixy = "0" ixz = "0" iyy = "0.1" iyz = "0" izz = "0.1" />
		</inertial>
		<collision>
			<origin rpy = "0 0 0"  xyz = "0 0 0" />
			<geometry>
				<sphere radius="2e-06" />
			</geometry>
		</collision>
	</link>
	<joint name="left_clavicle_ry" type="revolute">
		<parent link = "left_clavicle_rx" />
		<child link = "left_clavicle_ry" />
		<limit effort="1000.0" lower= "-0.6" upper= "0.4" velocity="0.5" />
		<origin rpy = "0 0 0" xyz ="0.0 0.0 0.0"  />
		<axis xyz = "0.0 0.0 1.0" />
	</joint>
	<link name = "left_clavicle_rz">
		<inertial>
			<origin rpy = "0 0 0"  xyz = "0 0 0" />
			<mass value =  "1e-05" />
			<inertia ixx = "0.1" ixy = "0" ixz = "0" iyy = "0.1" iyz = "0" izz = "0.1" />
		</inertial>
		<collision>
			<origin rpy = "0 0 0"  xyz = "0 0 0" />
			<geometry>
				<sphere radius="2e-05" />
			</geometry>
		</collision>
	</link>
	<joint name="left_clavicle_rz" type="revolute">
		<parent link = "left_clavicle_ry" />
		<child link = "left_clavicle_rz" />
		<limit effort="1000.0" lower= "-0.4" upper= "0.4" velocity="0.5" />
		<origin rpy = "0 0 0" xyz ="0.0 0.0 0.0"  />
		<axis xyz = "1.0 0.0 0.0" />
	</joint>
	<link name = "right_clavicle_rx">
		<inertial>
			<origin rpy = "0 0 0"  xyz = "0 0 0" />
			<mass value =  "1e-05" />
			<inertia ixx = "0.1" ixy = "0" ixz = "0" iyy = "0.1" iyz = "0" izz = "0.1" />
		</inertial>
		<collision>
			<origin rpy = "0 0 0"  xyz = "0 0 0" />
			<geometry>
				<sphere radius="2e-06" />
			</geometry>
		</collision>
	</link>
	<joint name="right_clavicle_rx" type="fixed">
		<parent link = "spine_4_rz" />
		<child link = "right_clavicle_rx" />
		<origin rpy = "0 0 0" xyz ="-0.020890837953153617 -0.07401918907398969 0.10060056108005375"  />
	</joint>
	<link name = "right_clavicle_ry">
		<inertial>
			<origin rpy = "0 0 0"  xyz = "0 0 0" />
			<mass value =  "1e-05" />
			<inertia ixx = "0.1" ixy = "0" ixz = "0" iyy = "0.1" iyz = "0" izz = "0.1" />
		</inertial>
		<collision>
			<origin rpy = "0 0 0"  xyz = "0 0 0" />
			<geometry>
				<sphere radius="2e-06" />
			</geometry>
		</collision>
	</link>
	<joint name="right_clavicle_ry" type="revolute">
		<parent link = "right_clavicle_rx" />
		<child link = "right_clavicle_ry" />
		<limit effort="1000.0" lower= "-0.4" upper= "0.6" velocity="0.5" />
		<origin rpy = "0 0 0" xyz ="0.0 0.0 0.0"  />
		<axis xyz = "0.0 0.0 1.0" />
	</joint>
	<link name = "right_clavicle_rz">
		<inertial>
			<origin rpy = "0 0 0"  xyz = "0 0 0" />
			<mass value =  "1e-05" />
			<inertia ixx = "0.1" ixy = "0" ixz = "0" iyy = "0.1" iyz = "0" izz = "0.1" />
		</inertial>
		<collision>
			<origin rpy = "0 0 0"  xyz = "0 0 0" />
			<geometry>
				<sphere radius="2e-05" />
			</geometry>
		</collision>
	</link>
	<joint name="right_clavicle_rz" type="revolute">
		<parent link = "right_clavicle_ry" />
		<child link = "right_clavicle_rz" />
		<limit effort="1000.0" lower= "-0.4" upper= "0.4" velocity="0.5" />
		<origin rpy = "0 0 0" xyz ="0.0 0.0 0.0"  />
		<axis xyz = "1.0 0.0 0.0" />
	</joint>
	<link name = "head_limb">
		<inertial>
			<origin rpy = "0 0 0"  xyz = "0.01262485 0.00252685 0.122528375" />
			<mass value =  "6" />
			<inertia ixx = "0.1" ixy = "0" ixz = "0" iyy = "0.1" iyz = "0" izz = "0.1" />
		</inertial>
		<collision>
			<origin rpy = "0 0 0"  xyz = "0.01262485 0.00252685 0.122528375" />
			<geometry>
				<sphere radius="0.08" />
			</geometry>
		</collision>
	</link>
	<joint name="neck_rzdammy" type="fixed">
		<parent link = "neck_rz" />
		<child link = "head_limb" />
		<origin rpy = "0 0 0" xyz ="0.0 0.0 0.0"  />
	</joint>
	<link name = "head_marker">
		<inertial>
			<origin rpy = "0 0 0"  xyz = "0.0 0.0 0.0" />
			<mass value =  "0.00001" />
			<inertia ixx = "0.1" ixy = "0" ixz = "0" iyy = "0.1" iyz = "0" izz = "0.1" />
		</inertial>
		<collision>
			<origin rpy = "0 0 0"  xyz = "0.0 0.0 0.0" />
			<geometry>
				<sphere radius="2e-06" />
			</geometry>
		</collision>
	</link>
	<joint name="head_marker" type="revolute">
		<parent link = "head_limb" />
		<child link = "head_marker" />
		<origin rpy = "0 0 0" xyz ="0.0 0.0 0.4100669268595065"  />
		<limit effort="1000.0" lower= "-2.0" upper= "0.6" velocity="0.5" />
		<axis xyz = "0.0 0.00000001 0.0" />
	</joint>
	<link name = "left_shoulder_limb">
		<inertial>
			<origin rpy = "0 0 0"  xyz = "-0.004516 0.030354250000000003 0.011370799999999999" />
			<mass value =  "2" />
			<inertia ixx = "0.1" ixy = "0" ixz = "0" iyy = "0.1" iyz = "0" izz = "0.1" />
		</inertial>
		<collision>
			<origin rpy = "0 0 0"  xyz = "-0.004516 0.084354250000000003 0.041370799999999999" />
			<geometry>
				<sphere radius="0.055" />
			</geometry>
		</collision>
	</link>
	<joint name="left_clavicle_rzdammy" type="fixed">
		<parent link = "left_clavicle_rz" />
		<child link = "left_shoulder_limb" />
		<origin rpy = "0 0 0" xyz ="0.0 0.0 0.0"  />
	</joint>
	<link name = "left_shoulder_rx">
		<inertial>
			<origin rpy = "0 0 0"  xyz = "0 0 0" />
			<mass value =  "1e-05" />
			<inertia ixx = "0.1" ixy = "0" ixz = "0" iyy = "0.1" iyz = "0" izz = "0.1" />
		</inertial>
		<collision>
			<origin rpy = "0 0 0"  xyz = "0 0 0" />
			<geometry>
				<sphere radius="2e-06" />
			</geometry>
		</collision>
	</link>
	<joint name="left_shoulder_rx" type="revolute">
		<parent link = "left_shoulder_limb" />
		<child link = "left_shoulder_rx" />
		<limit effort="1000.0" lower= "-2.0" upper= "0.6" velocity="0.5" />
		<origin rpy = "0 0 0" xyz ="-0.011133978735124393 0.09483692958827494 0.02803415531473703"  />
		<axis xyz = "0.0 1.0 0.0" />
	</joint>
	<link name = "left_shoulder_ry">
		<inertial>
			<origin rpy = "0 0 0"  xyz = "-0.00176 -0.0175 0.00925" />
			<mass value =  "1e-05" />
			<inertia ixx = "0.1" ixy = "0" ixz = "0" iyy = "0.1" iyz = "0" izz = "0.1" />
		</inertial>
		<collision>
			<origin rpy = "0 0 0"  xyz = "-0.00176 -0.0175 0.00925" />
			<geometry>
				<sphere radius="2e-07" />
			</geometry>
		</collision>
	</link>
	<joint name="left_shoulder_ry" type="revolute">
		<parent link = "left_shoulder_rx" />
		<child link = "left_shoulder_ry" />
		<limit effort="1000.0" lower= "-2.0" upper= "0.6" velocity="0.5" />
		<origin rpy = "0 0 0" xyz ="0.0 0.0 0.0"  />
		<axis xyz = "0.0 0.0 1.0" />
	</joint>
	<link name = "left_shoulder_rz">
		<inertial>
			<origin rpy = "0 0 0"  xyz = "0 0 0" />
			<mass value =  "1e-05" />
			<inertia ixx = "0.1" ixy = "0" ixz = "0" iyy = "0.1" iyz = "0" izz = "0.1" />
		</inertial>
		<collision>
			<origin rpy = "0 0 0"  xyz = "0 0 0" />
			<geometry>
				<sphere radius="2e-05" />
			</geometry>
		</collision>
	</link>
	<joint name="left_shoulder_rz" type="revolute">
		<parent link = "left_shoulder_ry" />
		<child link = "left_shoulder_rz" />
		<limit effort="1000.0" lower= "-1.0" upper= "1.0" velocity="0.5" />
		<origin rpy = "0 0 0" xyz ="0.0 0.0 0.0"  />
		<axis xyz = "1.0 0.0 0.0" />
	</joint>
	<link name = "right_shoulder_limb">
		<inertial>
			<origin rpy = "0 0 0"  xyz = "-0.001934565 -0.027959 0.011765925" />
			<mass value =  "2" />
			<inertia ixx = "0.1" ixy = "0" ixz = "0" iyy = "0.1" iyz = "0" izz = "0.1" />
		</inertial>
		<collision>
			<origin rpy = "0 0 0"  xyz = "-0.004516 -0.084354250000000003 0.041370799999999999" />
			<geometry>
				<sphere radius="0.055" />
			</geometry>
		</collision>
	</link>
	<joint name="right_clavicle_rzdammy" type="fixed">
		<parent link = "right_clavicle_rz" />
		<child link = "right_shoulder_limb" />
		<origin rpy = "0 0 0" xyz ="0.0 0.0 0.0"  />
	</joint>
	<link name = "right_shoulder_rx">
		<inertial>
			<origin rpy = "0 0 0"  xyz = "0 0 0" />
			<mass value =  "1e-05" />
			<inertia ixx = "0.1" ixy = "0" ixz = "0" iyy = "0.1" iyz = "0" izz = "0.1" />
		</inertial>
		<collision>
			<origin rpy = "0 0 0"  xyz = "0 0 0" />
			<geometry>
				<sphere radius="2e-06" />
			</geometry>
		</collision>
	</link>
	<joint name="right_shoulder_rx" type="revolute">
		<parent link = "right_shoulder_limb" />
		<child link = "right_shoulder_rx" />
		<limit effort="1000.0" lower= "-2.0" upper= "0.6" velocity="0.5" />
		<axis xyz = "0.0 1.0 0.0" />
		<origin rpy = "0 0 0" xyz ="-0.0048088503246344234 -0.09049916194413414 0.029247180764603038"  />
	</joint>
	<link name = "right_shoulder_ry">
		<inertial>
			<origin rpy = "0 0 0"  xyz = "-0.00176 0.0175 0.00925" />
			<mass value =  "1e-05" />
			<inertia ixx = "0.1" ixy = "0" ixz = "0" iyy = "0.1" iyz = "0" izz = "0.1" />
		</inertial>
		<collision>
			<origin rpy = "0 0 0"  xyz = "-0.00176 0.0175 0.00925" />
			<geometry>
				<sphere radius="2e-06" />
			</geometry>
		</collision>
	</link>
	<joint name="right_shoulder_ry" type="revolute">
		<parent link = "right_shoulder_rx" />
		<child link = "right_shoulder_ry" />
		<limit effort="1000.0" lower= "-0.6" upper= "2.0" velocity="0.5" />
		<origin rpy = "0 0 0" xyz ="0.0 0.0 0.0"  />
		<axis xyz = "0.0 0.0 1.0" />
	</joint>
	<link name = "right_shoulder_rz">
		<inertial>
			<origin rpy = "0 0 0"  xyz = "0 0 0" />
			<mass value =  "1e-05" />
			<inertia ixx = "0.1" ixy = "0" ixz = "0" iyy = "0.1" iyz = "0" izz = "0.1" />
		</inertial>
		<collision>
			<origin rpy = "0 0 0"  xyz = "0 0 0" />
			<geometry>
				<sphere radius="2e-05" />
			</geometry>
		</collision>
	</link>
	<joint name="right_shoulder_rz" type="revolute">
		<parent link = "right_shoulder_ry" />
		<child link = "right_shoulder_rz" />
		<limit effort="1000.0" lower= "-1.0" upper= "1.0" velocity="0.5" />
		<origin rpy = "0 0 0" xyz ="0.0 0.0 0.0"  />
		<axis xyz = "1.0 0.0 0.0" />
	</joint>
	<link name = "left_elbow_limb">
		<inertial>
			<origin rpy = "0 0 0"  xyz = "-0.005594275 0.064062 -0.004046999999999999" />
			<mass value =  "1.7" />
			<inertia ixx = "0.1" ixy = "0" ixz = "0" iyy = "0.1" iyz = "0" izz = "0.1" />
		</inertial>
		<collision>
			<origin rpy = "1.59 0 0"  xyz = "-0.005594275 0.14062 0.01048726" />
			<geometry>
				<cylinder radius="0.035" length="0.28"/>
			</geometry>
		</collision>

	</link>
	<joint name="left_shoulder_rzdammy" type="fixed">
		<parent link = "left_shoulder_rz" />
		<child link = "left_elbow_limb" />
		<origin rpy = "0 0 0" xyz ="0.0 0.0 0.0"  />
	</joint>
	<link name = "left_elbow_rx">
		<inertial>
			<origin rpy = "0 0 0"  xyz = "0 0 0" />
			<mass value =  "1e-05" />
			<inertia ixx = "0.1" ixy = "0" ixz = "0" iyy = "0.1" iyz = "0" izz = "0.1" />
		</inertial>
		<collision>
			<origin rpy = "0 0 0"  xyz = "0.00  0 0.024" />
			<geometry>
				<sphere radius="0.04" />
			</geometry>
		</collision>
	</link>
	<joint name="left_elbow_rx" type="revolute">
		<parent link = "left_elbow_limb" />
		<child link = "left_elbow_rx" />
		<limit effort="1000.0" lower= "-1.4" upper= "0.9" velocity="0.5" />
		<origin rpy = "0 0 0" xyz ="-0.00036473458152653463 0.31 -0.018557493477412382"  />
		<axis xyz = "0.0 1.0 0.0" />
	</joint>
	<link name = "left_elbow_ry">
		<inertial>
			<origin rpy = "0 0 0"  xyz = "0 0 0" />
			<mass value =  "1e-05" />
			<inertia ixx = "0.1" ixy = "0" ixz = "0" iyy = "0.1" iyz = "0" izz = "0.1" />
		</inertial>
		<collision>
			<origin rpy = "0 0 0"  xyz = "0 0 0" />
			<geometry>
				<sphere radius="2e-06" />
			</geometry>
		</collision>
	</link>
	<joint name="left_elbow_ry" type="revolute">
		<parent link = "left_elbow_rx" />
		<child link = "left_elbow_ry" />
		<limit effort="1000.0" lower= "-2.7" upper= "0.0" velocity="0.5" />
		<origin rpy = "0 0 0" xyz ="0.0 0.0 0.0"  />
		<axis xyz = "0.0 0.0 1.0" />
	</joint>
	<link name = "left_elbow_rz">
		<inertial>
			<origin rpy = "0 0 0"  xyz = "0 0 0" />
			<mass value =  "1e-05" />
			<inertia ixx = "0.1" ixy = "0" ixz = "0" iyy = "0.1" iyz = "0" izz = "0.1" />
		</inertial>
		<collision>
			<origin rpy = "0 0 0"  xyz = "0 0 0" />
			<geometry>
				<sphere radius="2e-05" />
			</geometry>
		</collision>
	</link>
	<joint name="left_elbow_rz" type="fixed">
		<parent link = "left_elbow_ry" />
		<child link = "left_elbow_rz" />
		<origin rpy = "0 0 0" xyz ="0.0 0.0 0.0"  />
	</joint>
	<link name = "right_elbow_limb">
		<inertial>
			<origin rpy = "0 0 0"  xyz ="-0.005594275 -0.14062 0.01048726" />
			<mass value =  "1.7" />
			<inertia ixx = "0.1" ixy = "0" ixz = "0" iyy = "0.1" iyz = "0" izz = "0.1" />
		</inertial>
		<collision>
			<origin rpy = "1.59 0 0"  xyz = "-0.005594275 -0.14062 0.01048726" />
			<geometry>
				<cylinder radius="0.035" length="0.28"/>
			</geometry>
		</collision>
	</link>
	<joint name="right_shoulder_rzdammy" type="fixed">
		<parent link = "right_shoulder_rz" />
		<child link = "right_elbow_limb" />
		<origin rpy = "0 0 0" xyz ="0.0 0.0 0.0"  />
	</joint>
	<link name = "right_elbow_rx">
		<inertial>
			<origin rpy = "0 0 0"  xyz = "0 0 0" />
			<mass value =  "1e-05" />
			<inertia ixx = "0.1" ixy = "0" ixz = "0" iyy = "0.1" iyz = "0" izz = "0.1" />
		</inertial>
		<collision>
		<origin rpy = "0 0 0"  xyz = "0.00 0 0.024" />
			<geometry>
				<sphere radius="0.04" />
			</geometry>
		</collision>
	</link>
	<joint name="right_elbow_rx" type="revolute">
		<parent link = "right_elbow_limb" />
		<child link = "right_elbow_rx" />
		<limit effort="1000.0" lower= "-1.4" upper= "0.9" velocity="0.5" />
		<origin rpy = "0 0 0" xyz ="-0.00035890767636245194 -0.31 -0.01826102377025329"  />
		<axis xyz = "0.0 1.0 0.0" />
	</joint>
	<link name = "right_elbow_ry">
		<inertial>
			<origin rpy = "0 0 0"  xyz = "0 0 0" />
			<mass value =  "1e-05" />
			<inertia ixx = "0.1" ixy = "0" ixz = "0" iyy = "0.1" iyz = "0" izz = "0.1" />
		</inertial>
		<collision>
			<origin rpy = "0 0 0"  xyz = "0 0 0" />
			<geometry>
				<sphere radius="2e-06" />
			</geometry>
		</collision>
	</link>
	<joint name="right_elbow_ry" type="revolute">
		<parent link = "right_elbow_rx" />
		<child link = "right_elbow_ry" />
		<limit effort="1000.0" lower= "0.0" upper= "2.7" velocity="0.5" />
		<origin rpy = "0 0 0" xyz ="0.0 0.0 0.0"  />
		<axis xyz = "0.0 0.0 1.0" />
	</joint>
	<link name = "right_elbow_rz">
		<inertial>
			<origin rpy = "0 0 0"  xyz = "0 0 0" />
			<mass value =  "1e-05" />
			<inertia ixx = "0.1" ixy = "0" ixz = "0" iyy = "0.1" iyz = "0" izz = "0.1" />
		</inertial>
		<collision>
			<origin rpy = "0 0 0"  xyz = "0 0 0" />
			<geometry>
				<sphere radius="2e-05" />
			</geometry>
		</collision>
	</link>
	<joint name="right_elbow_rz" type="fixed">
		<parent link = "right_elbow_ry" />
		<child link = "right_elbow_rz" />
		<origin rpy = "0 0 0" xyz ="0.0 0.0 0.0"  />
	</joint>
	<link name = "left_lowarm_limb">
		<inertial>
			<origin rpy = "0 0 0"  xyz = "-0.00191604 0.06645875 0.0031403750000000004" />
			<mass value =  "1" />
			<inertia ixx = "0.1" ixy = "0" ixz = "0" iyy = "0.1" iyz = "0" izz = "0.1" />
		</inertial>
		<collision>
			<origin rpy = "1.59 0 0"  xyz = " 0.0001791604 0.13645875 0.0231403750000000004" />
			<geometry>
				<cylinder radius="0.035" length="0.22"/>
			</geometry>
		</collision>

	</link>
	<joint name="left_elbow_rzdammy" type="fixed">
		<parent link = "left_elbow_rz" />
		<child link = "left_lowarm_limb" />
		<origin rpy = "0 0 0" xyz ="0.0 0.0 0.0"  />
	</joint>
	<link name = "left_lowarm_rx">
		<inertial>
			<origin rpy = "0 0 0"  xyz = "0 0 0" />
			<mass value =  "1e-05" />
			<inertia ixx = "0.1" ixy = "0" ixz = "0" iyy = "0.1" iyz = "0" izz = "0.1" />
		</inertial>
		<collision>
			<origin rpy = "0 0 0"  xyz = "0 0 0" />
			<geometry>
				<sphere radius="2e-06" />
			</geometry>
		</collision>
	</link>
	<joint name="left_lowarm_rx" type="fixed">
		<parent link = "left_lowarm_limb" />
		<child link = "left_lowarm_rx" />
		<origin rpy = "0 0 0" xyz ="-0.01069145196511791 0.258380478939792 0.017523208526417595"  />
	</joint>
	<link name = "left_lowarm_ry">
		<inertial>
			<origin rpy = "0 0 0"  xyz = "0 0 0" />
			<mass value =  "1e-05" />
			<inertia ixx = "0.1" ixy = "0" ixz = "0" iyy = "0.1" iyz = "0" izz = "0.1" />
		</inertial>
		<collision>
			<origin rpy = "0 0 0"  xyz = "0 0 0" />
			<geometry>
				<sphere radius="2e-06" />
			</geometry>
		</collision>
	</link>
	<joint name="left_lowarm_ry" type="fixed">
		<parent link = "left_lowarm_rx" />
		<child link = "left_lowarm_ry" />
		<origin rpy = "0 0 0" xyz ="0.0 0.0 0.0"  />
	</joint>
	<link name = "left_lowarm_rz">
		<inertial>
			<origin rpy = "0 0 0"  xyz = "0 0 0" />
			<mass value =  "1e-05" />
			<inertia ixx = "0.1" ixy = "0" ixz = "0" iyy = "0.1" iyz = "0" izz = "0.1" />
		</inertial>
		<collision>
			<origin rpy = "0 0 0"  xyz = "0 0 0" />
			<geometry>
				<sphere radius="2e-05" />
			</geometry>
		</collision>
	</link>
	<joint name="left_lowarm_rz" type="fixed">
		<parent link = "left_lowarm_ry" />
		<child link = "left_lowarm_rz" />
		<origin rpy = "0 0 0" xyz ="0.0 0.0 0.0"  />
	</joint>
	<link name = "right_lowarm_limb">
		<inertial>
			<origin rpy = "0 0 0"  xyz = "0.0001791604 -0.19645875 0.0231403750000000004" />
			<mass value =  "1" />
			<inertia ixx = "0.1" ixy = "0" ixz = "0" iyy = "0.1" iyz = "0" izz = "0.1" />
		</inertial>
		<collision>
			<origin rpy = "1.59 0 0"  xyz = "0.0001791604 -0.13645875 0.0231403750000000004" />
			<geometry>
				 <cylinder radius="0.035" length="0.22"/>
			</geometry>
		</collision>
	</link>
	<joint name="right_elbow_rzdammy" type="fixed">
		<parent link = "right_elbow_rz" />
		<child link = "right_lowarm_limb" />
		<origin rpy = "0 0 0" xyz ="0.0 0.0 0.0"  />
	</joint>
	<link name = "right_lowarm_rx">
		<inertial>
			<origin rpy = "0 0 0"  xyz = "0 0 0" />
			<mass value =  "1e-05" />
			<inertia ixx = "0.1" ixy = "0" ixz = "0" iyy = "0.1" iyz = "0" izz = "0.1" />
		</inertial>
		<collision>
			<origin rpy = "0 0 0"  xyz = "0 0 0" />
			<geometry>
				<sphere radius="2e-06" />
			</geometry>
		</collision>
	</link>
	<joint name="right_lowarm_rx" type="fixed">
		<parent link = "right_lowarm_limb" />
		<child link = "right_lowarm_rx" />
		<origin rpy = "0 0 0" xyz ="-0.008675505764860522 -0.258380478939792 0.010341347566117045"  />
	</joint>
	<link name = "right_lowarm_ry">
		<inertial>
			<origin rpy = "0 0 0"  xyz = "0 0 0" />
			<mass value =  "1e-05" />
			<inertia ixx = "0.1" ixy = "0" ixz = "0" iyy = "0.1" iyz = "0" izz = "0.1" />
		</inertial>
		<collision>
			<origin rpy = "0 0 0"  xyz = "0 0 0" />
			<geometry>
				<sphere radius="2e-06" />
			</geometry>
		</collision>
	</link>
	<joint name="right_lowarm_ry" type="fixed">
		<parent link = "right_lowarm_rx" />
		<child link = "right_lowarm_ry" />
		<origin rpy = "0 0 0" xyz ="0.0 0.0 0.0"  />
	</joint>
	<link name = "right_lowarm_rz">
		<inertial>
			<origin rpy = "0 0 0"  xyz = "0 0 0" />
			<mass value =  "1e-05" />
			<inertia ixx = "0.1" ixy = "0" ixz = "0" iyy = "0.1" iyz = "0" izz = "0.1" />
		</inertial>
		<collision>
			<origin rpy = "0 0 0"  xyz = "0 0 0" />
			<geometry>
				<sphere radius="2e-05" />
			</geometry>
		</collision>
	</link>
	<joint name="right_lowarm_rz" type="fixed">
		<parent link = "right_lowarm_ry" />
		<child link = "right_lowarm_rz" />
		<origin rpy = "0 0 0" xyz ="0.0 0.0 0.0"  />
	</joint>
	<link name = "left_hand_limb">
		<inertial>
			<origin rpy = "0 0 0"  xyz = "-0.0039015499999999997 0.02161905 -0.002651175" />
			<mass value =  "0.5" />
			<inertia ixx = "0.1" ixy = "0" ixz = "0" iyy = "0.1" iyz = "0" izz = "0.1" />
		</inertial>
		<collision>
			<origin rpy = "0 0 0"  xyz = "  0.000189015499999999997 0.02161905  0.009651175" />
			<geometry>
				<sphere radius="0.05" />
			</geometry>
		</collision>
	</link>
	<joint name="left_lowarm_rzdammy" type="revolute">
		<parent link = "left_lowarm_rz" />
		<child link = "left_hand_limb" />
		<origin rpy = "0 0 0" xyz ="0.0 0.0 0.0"  />
		<limit effort="1000.0" lower= "0" upper= "0" velocity="0.5" />
		<axis xyz = "0.0 1.0 0.0" />
	</joint>
	<link name = "left_hand_rx">
		<inertial>
			<origin rpy = "0 0 0"  xyz = "0 0 0" />
			<mass value =  "1e-05" />
			<inertia ixx = "0.1" ixy = "0" ixz = "0" iyy = "0.1" iyz = "0" izz = "0.1" />
		</inertial>
		<collision>
			<origin rpy = "0 0 0"  xyz = "0 0 0" />
			<geometry>
				<sphere radius="2e-06" />
			</geometry>
		</collision>
	</link>
	<joint name="left_hand_rx" type="fixed">
		<parent link = "left_hand_limb" />
		<child link = "left_hand_rx" />
		<origin rpy = "0 0 0" xyz ="-0.015606199999999999 0.0864762 -0.0106047"  />
	</joint>
	<link name = "left_hand_ry">
		<inertial>
			<origin rpy = "0 0 0"  xyz = "0 0 0" />
			<mass value =  "1e-05" />
			<inertia ixx = "0.1" ixy = "0" ixz = "0" iyy = "0.1" iyz = "0" izz = "0.1" />
		</inertial>
		<collision>
			<origin rpy = "0 0 0"  xyz = "0 0 0" />
			<geometry>
				<sphere radius="2e-06" />
			</geometry>
		</collision>
	</link>
	<joint name="left_hand_ry" type="fixed">
		<parent link = "left_hand_rx" />
		<child link = "left_hand_ry" />
		<origin rpy = "0 0 0" xyz ="0.0 0.0 0.0"  />
	</joint>
	<link name = "left_hand_rz">
		<inertial>
			<origin rpy = "0 0 0"  xyz = "0 0 0" />
			<mass value =  "1e-05" />
			<inertia ixx = "0.1" ixy = "0" ixz = "0" iyy = "0.1" iyz = "0" izz = "0.1" />
		</inertial>
		<collision>
			<origin rpy = "0 0 0"  xyz = "0 0 0" />
			<geometry>
				<sphere radius="2e-05" />
			</geometry>
		</collision>
	</link>
	<joint name="left_hand_rz" type="fixed">
		<parent link = "left_hand_ry" />
		<child link = "left_hand_rz" />
		<origin rpy = "0 0 0" xyz ="0.0 0.0 0.0"  />
	</joint>
	<link name = "right_hand_limb">
		<inertial>
			<origin rpy = "0 0 0"  xyz = "-0.0025347 -0.022091575 -0.0021468950000000002" />
			<mass value =  "0.5" />
			<inertia ixx = "0.1" ixy = "0" ixz = "0" iyy = "0.1" iyz = "0" izz = "0.1" />
		</inertial>
		<collision>
			<origin rpy = "0 0 0"  xyz = " 0.000189015499999999997 -0.02161905  0.009651175" />
			<geometry>
				<sphere radius="0.05" />
			</geometry>
		</collision>
	</link>
	<joint name="right_lowarm_rzdammy" type="revolute">
		<parent link = "right_lowarm_rz" />
		<child link = "right_hand_limb" />
		<origin rpy = "0 0 0" xyz ="0.0 0.0 0.0"  />
		<limit effort="1000.0" lower= "0" upper= "0" velocity="0.5" />
		<axis xyz = "0.0 1.0 0.0" />
	</joint>
	<link name = "right_hand_rx">
		<inertial>
			<origin rpy = "0 0 0"  xyz = "0 0 0" />
			<mass value =  "1e-05" />
			<inertia ixx = "0.1" ixy = "0" ixz = "0" iyy = "0.1" iyz = "0" izz = "0.1" />
		</inertial>
		<collision>
			<origin rpy = "0 0 0"  xyz = "0 0 0" />
			<geometry>
				<sphere radius="2e-06" />
			</geometry>
		</collision>
	</link>
	<joint name="right_hand_rx" type="fixed">
		<parent link = "right_hand_limb" />
		<child link = "right_hand_rx" />
		<origin rpy = "0 0 0" xyz ="-0.0101388 -0.0883663 -0.008587580000000001"  />
	</joint>
	<link name = "right_hand_ry">
		<inertial>
			<origin rpy = "0 0 0"  xyz = "0 0 0" />
			<mass value =  "1e-05" />
			<inertia ixx = "0.1" ixy = "0" ixz = "0" iyy = "0.1" iyz = "0" izz = "0.1" />
		</inertial>
		<collision>
			<origin rpy = "0 0 0"  xyz = "0 0 0" />
			<geometry>
				<sphere radius="2e-06" />
			</geometry>
		</collision>
	</link>
	<joint name="right_hand_ry" type="fixed">
		<parent link = "right_hand_rx" />
		<child link = "right_hand_ry" />
		<origin rpy = "0 0 0" xyz ="0.0 0.0 0.0"  />
	</joint>
	<link name = "right_hand_rz">
		<inertial>
			<origin rpy = "0 0 0"  xyz = "0 0 0" />
			<mass value =  "1e-05" />
			<inertia ixx = "0.1" ixy = "0" ixz = "0" iyy = "0.1" iyz = "0" izz = "0.1" />
		</inertial>
		<collision>
			<origin rpy = "0 0 0"  xyz = "0 0 0" />
			<geometry>
				<sphere radius="2e-05" />
			</geometry>
		</collision>
	</link>
	<joint name="right_hand_rz" type="fixed">
		<parent link = "right_hand_ry" />
		<child link = "right_hand_rz" />
		<origin rpy = "0 0 0" xyz ="0.0 0.0 0.0"  />
	</joint>
</robot>
